Workbook

Sheet Backlog
A1: ID | B1: Epic | C1: Epic name | D1: Story | E1: Persona | F1: Tier | G1: Priority | H1: Size | I1: Depends on | J1: Acceptance criteria | K1: Status | L1: Owner
A2: E00-01 | B2: E00 | C2: Platform and data foundation | D2: Accounts with a patient-owned health graph and linked family accounts; in-region hosting (SG or MY) | E2: System | F2: T1 | G2: P1 | H2: L | J2: Patient node owns all data; family accounts attach via grants; data at rest in region | K2: Backlog
A3: E00-02 | B3: E00 | C3: Platform and data foundation | D3: Consent capture at onboarding: explicit, revocable, versioned, exportable as a PDPA record | E3: All | F3: T1 | G3: P1 | H3: M | J3: Consent event stored with timestamp, scope and version; revocation removes access within a minute | K3: Backlog
A4: E00-03 | B4: E00 | C4: Platform and data foundation | D4: Memory stores: episodic (raw artefacts), semantic (facts), working (current episode) with provenance on every fact | E4: System | F4: T1 | G4: P1 | H4: L | J4: Every semantic fact links to at least one artefact and a confidence | K4: Backlog
A5: E00-04 | B5: E00 | C5: Platform and data foundation | D5: State model service recomputing clinical, functional, cognitive, situational, preference and family state | E5: System | F5: T1 | G5: P1 | H5: L | I5: E00-03 | J5: State recomputes on any new fact; every card records the State it was rendered from | K5: Backlog
A6: E00-05 | B6: E00 | C6: Platform and data foundation | D6: Trigger engine implementing rule, pattern and event triggers with per-type channel and daily caps | E6: System | F6: T1 | G6: P1 | H6: M | I6: E00-04 | J6: No persona receives more than the configured cap per day; every trigger logs its rule | K6: Backlog
A7: E00-06 | B7: E00 | C7: Platform and data foundation | D7: Licensed drug database and interaction API integration (local registries MY NPRA, SG HSA) | E7: System | F7: T1 | G7: P1 | H7: M | J7: Brand to generic resolution for a sample of 200 MY/SG products above 95% | K7: Backlog
A8: E00-07 | B8: E00 | C8: Platform and data foundation | D8: Audit log service for every read, write and share | E8: System | F8: T1 | G8: P1 | H8: S | J8: Any access to patient data is queryable by patient and chief | K8: Backlog
A9: E00-08 | B9: E00 | C9: Platform and data foundation | D9: Offline cache for today's medicine list and emergency card; runs on five-year-old Android at 360px | E9: Dad | F9: T1 | G9: P1 | H9: M | J9: Cold start under 3s on a reference low-end device; card readable with no data | K9: Backlog
A10: E00-09 | B10: E00 | C10: Platform and data foundation | D10: Export (PDF, FHIR bundle) and full deletion | E10: All | F10: T2 | G10: P2 | H10: M | I10: E00-03 | J10: Export completes under 60s; deletion removes all stores and confirms | K10: Backlog
A11: E01-01 | B11: E01 | C11: Onboarding and health biography | D11: Chief-led onboarding: who the patient is, who the family is, roles and language | E11: Chief | F11: T1 | G11: P1 | H11: M | I11: E00-02 | J11: Complete in under 10 minutes with no typed fields beyond names | K11: Backlog
A12: E01-02 | B12: E01 | C12: Onboarding and health biography | D12: Health biography session: guided capture of existing papers into the record with agent assistance | E12: Chief | F12: T1 | G12: P1 | H12: L | I12: E02-01,E02-02 | J12: A shoebox of 30 documents becomes a reconciled record in one sitting | K12: Backlog
A13: E01-03 | B13: E01 | C13: Onboarding and health biography | D13: Patient profile: conditions, language, functional and cognitive settings | E13: Chief | F13: T1 | G13: P1 | H13: S | I13: E01-01 | J13: Settings drive density mode and voice language immediately | K13: Backlog
A14: E01-04 | B14: E01 | C14: Onboarding and health biography | D14: First-week activation plan: what to snap next, one prompt per day | E14: Chief | F14: T1 | G14: P2 | H14: S | I14: E01-02 | J14: Prompts stop once the record has medicines, last visit and next visit | K14: Backlog
A15: E02-01 | B15: E02 | C15: Capture and ingestion | D15: Photo to OCR to structured extraction for labs, reports, prescriptions and receipts | E15: Chief | F15: T1 | G15: P1 | H15: L | I15: E00-03 | J15: Lab values extracted with unit and date at 95% on a labelled MY/SG test set | K15: Backlog
A16: E02-02 | B16: E02 | C16: Capture and ingestion | D16: Handwriting recognition for clinic slips and handwritten prescriptions | E16: Chief | F16: T1 | G16: P1 | H16: L | I16: E02-01 | J16: Drug, dose and frequency read from handwritten slips with confidence shown | K16: Backlog
A17: E02-03 | B17: E02 | C17: Capture and ingestion | D17: PDF import from portals, email and shares | E17: Chief | F17: T1 | G17: P1 | H17: S | I17: E02-01 | J17: Multi-page PDFs parsed into events with dates | K17: Backlog
A18: E02-04 | B18: E02 | C18: Capture and ingestion | D18: WhatsApp inbound ingestion: forward a photo or PDF to the app number and it files itself | E18: All | F18: T1 | G18: P1 | H18: M | I18: E02-01,E11-01 | J18: Forwarded item appears in the record with a confirmation reply within a minute | K18: Backlog
A19: E02-05 | B19: E02 | C19: Capture and ingestion | D19: Consult recording with consent prompt, transcription, speaker separation and timestamps | E19: Chief | F19: T1 | G19: P1 | H19: L | I19: E00-02 | J19: Consent captured before recording; transcript searchable; clip playable at a timestamp | K19: Backlog
A20: E02-06 | B20: E02 | C20: Capture and ingestion | D20: Scribble and voice notes attached to any event | E20: All | F20: T1 | G20: P2 | H20: S | I20: E03-02 | J20: Note attaches to the selected event and appears in recall | K20: Backlog
A21: E02-07 | B21: E02 | C21: Capture and ingestion | D21: Capture review card with per-field confidence and one confirm tap | E21: Chief | F21: T1 | G21: P1 | H21: M | I21: E02-01 | J21: Fields below threshold shown dotted; a single tap saves | K21: Backlog
... A111: E14-03 | B111: E14 | C111: Symptoms and observations | D111: Mood and energy one-tap only when a condition or medicine makes it relevant | E111: Dad | F111: T3 | G111: P3 | H111: S | I111: E00-04 | J111: Gated by State; never framed clinically | K111: Backlog
A112: E15-01 | B112: E15 | C112: Design system and accessibility | D112: Design tokens, state washes, glass and paper components | E112: System | F112: T1 | G112: P1 | H112: M | J112: Tokens match design-system.md; washes cross-fade on State change | K112: Backlog
A113: E15-02 | B113: E15 | C113: Design system and accessibility | D113: Dad density mode: 20px body, 56px targets, paper-first, one action per tile | E113: Dad | F113: T1 | G113: P1 | H113: M | I113: E15-01 | J113: Contrast 7:1 on every decision element | K113: Backlog
A114: E15-03 | B114: E15 | C114: Design system and accessibility | D114: Chief density mode: glass-first, 16px body | E114: Chief | F114: T1 | G114: P1 | H114: M | I114: E15-01 | J114: Dense screens remain readable at 360px | K114: Backlog
A115: E15-04 | B115: E15 | C115: Design system and accessibility | D115: Accessibility audit: contrast, dynamic type to 200%, reduced motion | E115: All | F115: T1 | G115: P1 | H115: S | I115: E15-02 | J115: Audit passes before T1 release | K115: Backlog
A116: E15-05 | B116: E15 | C116: Design system and accessibility | D116: Localisation framework: Malay, Mandarin, English text; Tamil and Hokkien voice | E116: All | F116: T1 | G116: P1 | H116: M | J116: Every string externalised; voice language per person | K116: Backlog
A117: E15-06 | B117: E15 | C117: Design system and accessibility | D117: Body-systems map component | E117: All | F117: T2 | G117: P2 | H117: M | I117: E15-01 | J117: Outline figure with soft glows; doubles as filter | K117: Backlog
A118: E15-07 | B118: E15 | C118: Design system and accessibility | D118: Clip and voice-note player | E118: Dad | F118: T1 | G118: P2 | H118: S | I118: E15-01 | J118: Large play target; transcript in Dad body size | K118: Backlog
A119: E16-01 | B119: E16 | C119: Trust, boundary and regulatory | D119: Boundary copy on every inferring screen | E119: All | F119: T1 | G119: P1 | H119: S | I119: E15-01 | J119: Organises, prepares, surfaces patterns to discuss; does not diagnose or treat | K119: Backlog
A120: E16-02 | B120: E16 | C120: Trust, boundary and regulatory | D120: Recording consent pattern with legal review in SG and MY | E120: All | F120: T1 | G120: P1 | H120: S | I120: E02-05 | J120: Doctor notified aloud or by printed notice; consent stored | K120: Backlog
A121: E16-03 | B121: E16 | C121: Trust, boundary and regulatory | D121: SaMD boundary review (HSA, MDA): guideline-referenced, non-real-time, informational outputs | E121: System | F121: T1 | G121: P1 | H121: M | I121: E09-03 | J121: Written review signed off before any flag ships | K121: Backlog
A122: E16-04 | B122: E16 | C122: Trust, boundary and regulatory | D122: High-risk drug rule: label photo required before a dose is saved | E122: System | F122: T1 | G122: P1 | H122: S | I122: E04-01 | J122: Warfarin, insulin, digoxin, methotrexate, opioids cannot be saved from voice alone | K122: Backlog
A123: E16-05 | B123: E16 | C123: Trust, boundary and regulatory | D123: PDPA data map, breach process and DPO | E123: System | F123: T1 | G123: P1 | H123: M | I123: E00-01 | J123: Data map covers both countries; breach runbook tested | K123: Backlog
A124: E17-01 | B124: E17 | C124: Feeling cloud and smart nudges | D124: State-conditioned feeling cloud on Today: base words plus emphasis and additions from State; shown only after a change, at most once a day | E124: Patient | F124: T1 | G124: P1 | H124: M | I124: E00-04 | J124: Words re-rank within a second of a State change; disappears after a tap or Fine today | K124: Backlog
A125: E17-02 | B125: E17 | C125: Feeling cloud and smart nudges | D125: Feeling inference: tap plus one follow-up read against medicines, readings and this week's changes; outcomes logged, watched, added to questions, or escalated | E125: System | F125: T1 | G125: P1 | H125: L | I125: E17-01,E04-01 | J125: Red flags open not-feeling-well and notify the roster within one minute; every inference names its reason | K125: Backlog
A126: E17-03 | B126: E17 | C126: Feeling cloud and smart nudges | D126: Smart nudge engine: presence, commitment, pattern, check-in, recognition, anticipation, curiosity, context; two a day; quiet hours; none on alert days | E126: System | F126: T1 | G126: P1 | H126: L | I126: E00-04,E05-06 | J126: Cap enforced per profile per day; every nudge carries why; dismissals feed ranking | K126: Backlog
A127: E17-04 | B127: E17 | C127: Feeling cloud and smart nudges | D127: The number that only goes up on Me | E127: Patient | F127: T1 | G127: P2 | H127: S | I127: E04-02 | J127: Never decreases; no streak language | K127: Backlog
A128: E17-05 | B128: E17 | C128: Feeling cloud and smart nudges | D128: Nudge and check-in metrics: taps per week, Fine-today share, acceptance by kind | E128: System | F128: T1 | G128: P2 | H128: S | I128: E17-03 | J128: Dashboard shows weekly counts per profile | K128: Backlog
... A135: E18-07 | B135: E18 | C135: Read-only connectors | D135: Connector rules enforcement and audit: purpose-bound, allowlisted, shown before stored, nothing trains anything | E135: System | F135: T2 | G135: P1 | H135: M | I135: E16-05 | J135: Every connector ingestion has an audit entry visible to the owner | K135: Backlog
...

Sheet Epics
A1: Epic | B1: Epic name | C1: Stories | D1: T1 | E1: T2 | F1: T3 | G1: P1 | H1: Large
A2: E00 | B2: Platform and data foundation | C2: =COUNTIF(Backlog!$B:$B,A2) -> 9 | D2: =COUNTIFS(Backlog!$B:$B,A2,Backlog!$F:$F,"T1") -> 8 | E2: =COUNTIFS(Backlog!$B:$B,A2,Backlog!$F:$F,"T2") -> 1 | F2: =COUNTIFS(Backlog!$B:$B,A2,Backlog!$F:$F,"T3") -> 0 | G2: =COUNTIFS(Backlog!$B:$B,A2,Backlog!$G:$G,"P1") -> 8 | H2: =COUNTIFS(Backlog!$B:$B,A2,Backlog!$H:$H,"L") -> 3
A3: E01 | B3: Onboarding and health biography | C3: =COUNTIF(Backlog!$B:$B,A3) -> 4 | D3: =COUNTIFS(Backlog!$B:$B,A3,Backlog!$F:$F,"T1") -> 4 | E3: =COUNTIFS(Backlog!$B:$B,A3,Backlog!$F:$F,"T2") -> 0 | F3: =COUNTIFS(Backlog!$B:$B,A3,Backlog!$F:$F,"T3") -> 0 | G3: =COUNTIFS(Backlog!$B:$B,A3,Backlog!$G:$G,"P1") -> 3 | H3: =COUNTIFS(Backlog!$B:$B,A3,Backlog!$H:$H,"L") -> 1
A4: E02 | B4: Capture and ingestion | C4: =COUNTIF(Backlog!$B:$B,A4) -> 11 | D4: =COUNTIFS(Backlog!$B:$B,A4,Backlog!$F:$F,"T1") -> 8 | E4: =COUNTIFS(Backlog!$B:$B,A4,Backlog!$F:$F,"T2") -> 3 | F4: =COUNTIFS(Backlog!$B:$B,A4,Backlog!$F:$F,"T3") -> 0 | G4: =COUNTIFS(Backlog!$B:$B,A4,Backlog!$G:$G,"P1") -> 7 | H4: =COUNTIFS(Backlog!$B:$B,A4,Backlog!$H:$H,"L") -> 4
A5: E03 | B5: Memory and timeline | C5: =COUNTIF(Backlog!$B:$B,A5) -> 7 | D5: =COUNTIFS(Backlog!$B:$B,A5,Backlog!$F:$F,"T1") -> 5 | E5: =COUNTIFS(Backlog!$B:$B,A5,Backlog!$F:$F,"T2") -> 2 | F5: =COUNTIFS(Backlog!$B:$B,A5,Backlog!$F:$F,"T3") -> 0 | G5: =COUNTIFS(Backlog!$B:$B,A5,Backlog!$G:$G,"P1") -> 5 | H5: =COUNTIFS(Backlog!$B:$B,A5,Backlog!$H:$H,"L") -> 1
A6: E04 | B6: Medications | C6: =COUNTIF(Backlog!$B:$B,A6) -> 16 | D6: =COUNTIFS(Backlog!$B:$B,A6,Backlog!$F:$F,"T1") -> 7 | E6: =COUNTIFS(Backlog!$B:$B,A6,Backlog!$F:$F,"T2") -> 8 | F6: =COUNTIFS(Backlog!$B:$B,A6,Backlog!$F:$F,"T3") -> 1 | G6: =COUNTIFS(Backlog!$B:$B,A6,Backlog!$G:$G,"P1") -> 8 | H6: =COUNTIFS(Backlog!$B:$B,A6,Backlog!$H:$H,"L") -> 1
A7: E05 | B7: Visit loop | C7: =COUNTIF(Backlog!$B:$B,A7) -> 10 | D7: =COUNTIFS(Backlog!$B:$B,A7,Backlog!$F:$F,"T1") -> 6 | E7: =COUNTIFS(Backlog!$B:$B,A7,Backlog!$F:$F,"T2") -> 4 | F7: =COUNTIFS(Backlog!$B:$B,A7,Backlog!$F:$F,"T3") -> 0 | G7: =COUNTIFS(Backlog!$B:$B,A7,Backlog!$G:$G,"P1") -> 8 | H7: =COUNTIFS(Backlog!$B:$B,A7,Backlog!$H:$H,"L") -> 1
A8: E06 | B8: Discharge and transitions | C8: =COUNTIF(Backlog!$B:$B,A8) -> 5 | D8: =COUNTIFS(Backlog!$B:$B,A8,Backlog!$F:$F,"T1") -> 0 | E8: =COUNTIFS(Backlog!$B:$B,A8,Backlog!$F:$F,"T2") -> 4 | F8: =COUNTIFS(Backlog!$B:$B,A8,Backlog!$F:$F,"T3") -> 1 | G8: =COUNTIFS(Backlog!$B:$B,A8,Backlog!$G:$G,"P1") -> 3 | H8: =COUNTIFS(Backlog!$B:$B,A8,Backlog!$H:$H,"L") -> 2
A9: E07 | B9: Insurance, cost and admin | C9: =COUNTIF(Backlog!$B:$B,A9) -> 6 | D9: =COUNTIFS(Backlog!$B:$B,A9,Backlog!$F:$F,"T1") -> 0 | E9: =COUNTIFS(Backlog!$B:$B,A9,Backlog!$F:$F,"T2") -> 5 | F9: =COUNTIFS(Backlog!$B:$B,A9,Backlog!$F:$F,"T3") -> 1 | G9: =COUNTIFS(Backlog!$B:$B,A9,Backlog!$G:$G,"P1") -> 3 | H9: =COUNTIFS(Backlog!$B:$B,A9,Backlog!$H:$H,"L") -> 1
A10: E08 | B10: Care navigation | C10: =COUNTIF(Backlog!$B:$B,A10) -> 5 | D10: =COUNTIFS(Backlog!$B:$B,A10,Backlog!$F:$F,"T1") -> 0 | E10: =COUNTIFS(Backlog!$B:$B,A10,Backlog!$F:$F,"T2") -> 0 | F10: =COUNTIFS(Backlog!$B:$B,A10,Backlog!$F:$F,"T3") -> 5 | G10: =COUNTIFS(Backlog!$B:$B,A10,Backlog!$G:$G,"P1") -> 2 | H10: =COUNTIFS(Backlog!$B:$B,A10,Backlog!$H:$H,"L") -> 1
A11: E09 | B11: Intelligence and correlation | C11: =COUNTIF(Backlog!$B:$B,A11) -> 7 | D11: =COUNTIFS(Backlog!$B:$B,A11,Backlog!$F:$F,"T1") -> 1 | E11: =COUNTIFS(Backlog!$B:$B,A11,Backlog!$F:$F,"T2") -> 5 | F11: =COUNTIFS(Backlog!$B:$B,A11,Backlog!$F:$F,"T3") -> 1 | G11: =COUNTIFS(Backlog!$B:$B,A11,Backlog!$G:$G,"P1") -> 3 | H11: =COUNTIFS(Backlog!$B:$B,A11,Backlog!$H:$H,"L") -> 3
A12: E10 | B12: Daily living and routines | C12: =COUNTIF(Backlog!$B:$B,A12) -> 4 | D12: =COUNTIFS(Backlog!$B:$B,A12,Backlog!$F:$F,"T1") -> 1 | E12: =COUNTIFS(Backlog!$B:$B,A12,Backlog!$F:$F,"T2") -> 1 | F12: =COUNTIFS(Backlog!$B:$B,A12,Backlog!$F:$F,"T3") -> 2 | G12: =COUNTIFS(Backlog!$B:$B,A12,Backlog!$G:$G,"P1") -> 1 | H12: =COUNTIFS(Backlog!$B:$B,A12,Backlog!$H:$H,"L") -> 1
A13: E11 | B13: Delivery, feed and WhatsApp | C13: =COUNTIF(Backlog!$B:$B,A13) -> 10 | D13: =COUNTIFS(Backlog!$B:$B,A13,Backlog!$F:$F,"T1") -> 8 | E13: =COUNTIFS(Backlog!$B:$B,A13,Backlog!$F:$F,"T2") -> 1 | F13: =COUNTIFS(Backlog!$B:$B,A13,Backlog!$F:$F,"T3") -> 1 | G13: =COUNTIFS(Backlog!$B:$B,A13,Backlog!$G:$G,"P1") -> 7 | H13: =COUNTIFS(Backlog!$B:$B,A13,Backlog!$H:$H,"L") -> 3
... A24: E22 | B24: Plain words and voice | C24: =COUNTIF(Backlog!$B:$B,A24) -> 4 | D24: =COUNTIFS(Backlog!$B:$B,A24,Backlog!$F:$F,"T1") -> 4 | E24: =COUNTIFS(Backlog!$B:$B,A24,Backlog!$F:$F,"T2") -> 0 | F24: =COUNTIFS(Backlog!$B:$B,A24,Backlog!$F:$F,"T3") -> 0 | G24: =COUNTIFS(Backlog!$B:$B,A24,Backlog!$G:$G,"P1") -> 4 | H24: =COUNTIFS(Backlog!$B:$B,A24,Backlog!$H:$H,"L") -> 0
A25: Total | C25: =SUM(C2:C24) -> 154 | D25: =SUM(D2:D24) -> 89 | E25: =SUM(E2:E24) -> 46 | F25: =SUM(F2:F24) -> 19 | G25: =SUM(G2:G24) -> 102 | H25: =SUM(H2:H24) -> 32

Sheet Legend
A1: Column | B1: Meaning
A2: ID | B2: Epic code plus a running number. Stable once assigned.
A3: Persona | B3: Dad = patient surface. Chief = adult-child caregiver. Helper = domestic helper on WhatsApp. Clinic = doctor-facing output. All = more than one. System = backend or platform.
A4: Tier | B4: T1 = weeks 0-12, the daily loop. T2 = weeks 12-24, the clinical loop. T3 = weeks 24-36, navigation and media. All three are Stage 1.
A5: Priority | B5: P1 must ship in its tier. P2 should ship in its tier. P3 can slip a tier.
A6: Size | B6: S under a week for a pair. M one to two weeks. L three weeks or more, split before building.
A7: Depends on | B7: IDs that must be done first. Empty means none.
A8: Acceptance criteria | B8: The one test that says the story is done. Expand into scenarios when picked up.
A9: Status, Owner | B9: Fill these in. Status values: Backlog, Ready, In progress, Review, Done.
A11: Source | B11: Stories consolidate stage1-product-design.md, medications-module.md and design-system.md. Sizes and priorities are the author's estimates and should be re-pointed by the team.
